Workbook

Sheet Instructions
A2: Business Review
A3: Monthly Input | B3: 2016 Monthly Numbers…input your numbers here
A4: 2015byMonth | B4: 2015 Monthly Numbers. Copy and Paste values from 2015 QBR.
A5: QBR 2016 | B5: Reads Monthly Input
A6: QBR 2015 | B6: Reads 2015byMonth
A7: QBRCompare | B7: Reads QBR 2015 and QBR 2016
A8: SmartNumbers2016 | B8: Reads QBR2016
A9: SmartNumbers2015-2016 | B9: Reads SmartNumbers2016 and QBR2015
A10: SmartNumbers2016byMonthly | B10: Reads Monthly Input
A11: Charts2015-2016 | B11: Reads SmartNumberswith2015-2016 and reads Ranges.
A12: Charts2016 | B12: Reads Smart Numbers2016 and Ranges.
A13: Charts2016byMonth | B13: Reads SmartNumber2016 byMonth and Ranges
A14: Ranges | B14: Used for Chart tabs.
A17: 2016 Changes to Smart Numbers | B17: No more Endpoints Support by Tech
B18: Renamed RHEM from hours/Endpoint/month---name change only
A20: Bright Gauge - top left look for smart numbers dashboard

Sheet MonthlyINPUT
A3: Monthly Business Review 2025
C6: Jan | D6: Feb | E6: Mar | F6: Apr | G6: May | H6: June | I6: July | J6: August | K6: Sept | L6: Oct | M6: Nov | N6: Dec | O6: Total
B7: Category | C7: Amount
A8: Operations
B9: # of Reactive Tickets Created | C9: 354 | D9: 294 | E9: 433 | F9: 377 | G9: 386 | H9: 478 | I9: 542 | J9: 249 | K9: 289 | L9: 361
B10: # of Reactive Tickets Closed | C10: 355 | D10: 294 | E10: 431 | F10: 373 | G10: 385 | H10: 473 | I10: 549 | J10: 246 | K10: 291 | L10: 354
B11: Total Time on Reactive Tickets | C11: 146.46 | D11: 138.3 | E11: 167.44 | F11: 204.87 | G11: 148.33 | H11: 47.02
B12: # of Endpoints Managed | C12: =546+51 -> 597 | D12: =543+51 -> 594 | E12: =542+49 -> 591 | F12: =564+49 -> 613 | G12: =585+55 -> 640 | H12: =551+50 -> 601 | I12: =548+49 -> 597 | J12: =511+49 -> 560 | K12: =509+49 -> 558 | L12: =524+51 -> 575 | M12: =529+50 -> 579
A14: Revenue
B15: Non-recurring Revenue (NRR) | C15: -2043.75 | D15: 10877.06 | E15: 23445.5 | F15: 3978.61 | G15: 2989.5 | H15: 2384 | I15: 3557 | J15: 10725.25 | K15: 13798 | L15: 21264 | O15: =SUM(C15:N15) -> 90975.17
B16: Monthly Recurring Revenue (MRR) | C16: =105668.31+4013.95 -> 109682.26 | D16: =106209.48+4064.95 -> 110274.43 | E16: =105475.92+4526.95 -> 110002.87 | F16: =108569.08+4976.36 -> 113545.44 | G16: =112007.55+5001.43 -> 117008.98 | H16: =107253.57+5018.87 -> 112272.44 | I16: =109136.74+4883.15 -> 114019.89 | J16: =102480.21+4988.46 -> 107468.67 | K16: =101698.82+4556.33 -> 106255.15 | L16: =104661.15+4566.14 -> 109227.29 | O16: =SUM(C16:N16) -> 1109757.4
B17: Other Recurring Revenue (ORR) | C17: =68.54+25587.02+1079.93+613.32+830.95 -> 28179.76 | D17: =10877.06+49851.42+1079.93+644.19+832.58 -> 63285.18 | E17: =150.73+12836.45+633.62+834.13+1079.93 -> 15534.86 | F17: =10491.31+16280.43+1079.93+637.09+834.14 -> 29322.9 | G17: =21324.73+12651.69+1447.43+637.56+940.76 -> 37002.17 | H17: =587.52+14497.26+654.19+794.06 -> 16533.03 | I17: =83.13+15667.89+2159.52+652+797.32 -> 19359.86 | J17: =6389.08+10801.4+1081.38+571.87+795.69 -> 19639.42 | K17: =13689.45+551.02+2063.71+1081.38+798.69 -> 18184.25 | L17: =19.9+11245.36+1081.38 -> 12346.64 | O17: =SUM(C17:N17) -> 259388.07
B18: Product Sales | C18: =152294.29-C17-C16-C15 -> 16476.02 | D18: =187085.31-D17-D16-D15 -> 2648.64 | E18: =176108.55-E17-E16-E15 -> 27125.32 | F18: =157294.09-F17-F16-F15 -> 10447.14 | G18: =165395.59-G15-G16-G17 -> 8394.94 | H18: =144454.63-H15-H16-H17 -> 13265.16 | I18: =153162.98-I15-I16-I17 -> 16226.23 | J18: =151531.46-J15-J16-J17 -> 13698.12 | K18: =202515.11-K15-K16-K17 -> 64277.71 | L18: =180986.42-L15-L16-L17 -> 38148.49 | O18: =SUM(C18:N18) -> 210707.77
B19: Miscellaneous revenue | O19: =SUM(C19:N19) -> 0
B20: Total Revenue | C20: =SUM(C15:C19) -> 152294.29 | D20: =SUM(D15:D19) -> 187085.31 | E20: =SUM(E15:E19) -> 176108.55 | F20: =SUM(F15:F19) -> 157294.09 | G20: =SUM(G15:G19) -> 165395.59 | H20: =SUM(H15:H19) -> 144454.63 | I20: =SUM(I15:I19) -> 153162.98 | J20: =SUM(J15:J19) -> 151531.46 | ... N20: =SUM(N15:N19) -> 0 | O20: =SUM(C20:N20) -> 1670828.4
B21: 2024 | C21: =+'2024byMonth'!C20 -> 118759.05 | D21: =+'2024byMonth'!D20 -> 178966.62 | E21: =+'2024byMonth'!E20 -> 147575.8 | F21: =+'2024byMonth'!F20 -> 148185.27 | G21: =+'2024byMonth'!G20 -> 144020.36 | H21: =+'2024byMonth'!H20 -> 148343.7 | I21: =+'2024byMonth'!I20 -> 128202.47 | J21: =+'2024byMonth'!J20 -> 144222.34 | ... N21: =+'2024byMonth'!N20 -> 176513.61 | O21: =SUM(C21:N21) -> 1789500.2
A22: Expenses
B23: Employee Expense | C23: =66330.23-C24-C25 -> 38741.763 | D23: =65653.63-D24-D25 -> 38065.163 | E23: =79091.72-E24-E25 -> 38803.253 | F23: =67453.98-F24-F25 -> 38865.513 | G23: =67685.84-G24-G25 -> 39097.373 | H23: =85146.14-H24-H25 -> 33557.673 | I23: =73670.9-I24-I25 -> 39082.433 | J23: =72836.06-J24-J25 -> 38247.593 | K23: =70345.47-K24-K25 -> 35757.003 | L23: =72376.92-L24-L25 -> 37788.453 | O23: =SUM(C23:N23) -> 378006.22
B24: Owner Comp to pay QTR est taxes | C24: =5000 -> 5000 | D24: =5000 -> 5000 | E24: =5000+6000+2800+3900 -> 17700 | F24: 6000 | G24: 6000 | H24: =12000+17000 -> 29000 | I24: 12000 | J24: 12000 | K24: 12000 | L24: 12000 | O24: =SUM(C24:N24) -> 116700
B25: Owner Compensation | C25: =(67500+35600)/12+(1996.8)+12000 -> 22588.467 | D25: =(67500+35600)/12+(1996.8)+12000 -> 22588.467 | E25: =(67500+35600)/12+(1996.8)+12000 -> 22588.467 | F25: =(67500+35600)/12+(1996.8)+12000 -> 22588.467 | G25: =(67500+35600)/12+(1996.8)+12000 -> 22588.467 | H25: =(67500+35600)/12+(1996.8)+12000 -> 22588.467 | I25: =(67500+35600)/12+(1996.8)+12000 -> 22588.467 | J25: =(67500+35600)/12+(1996.8)+12000 -> 22588.467 | ... L25: =(67500+35600)/12+(1996.8)+12000 -> 22588.467 | O25: =SUM(C25:N25) -> 225884.67 | P25: Rmm $175K 2025
B26: Product Cost of Goods Sold (COGS) | C26: 21126.05 | D26: =(19127.2+51443) -> 70570.2 | E26: =78949.59-51443 -> 27506.59 | F26: 19740.19 | G26: 23999.39 | H26: 18382.51 | I26: 22458.72 | J26: 21578.91 | K26: 56436.99 | L26: 33684.99 | O26: =SUM(C26:N26) -> 315484.54 | P26: jmm$72K 2025 | Q26: note the $24K is for TCM and PVM
B27: All Other Expenses | C27: =(116373.11)-C23-C24-C25 -> 50042.88 | D27: =(106526.23)-D23-D24-D25 -> 40872.6 | E27: =(119384.52)-E23-E24-E25 -> 40292.8 | F27: =(107759.58)-F23-F24-F25 -> 40305.6 | G27: =(119305.09)-G23-G24-G25 -> 51619.25 | H27: =(127247.6)-H23-H24-H25 -> 42101.46 | I27: =(115125.26)-I23-I24-I25 -> 41454.36 | J27: =(116154.23)-J23-J24-J25 -> 43318.17 | K27: =(115274.63)-K23-K24-K25 -> 44929.16 | L27: =(126944.68-11115.85)-L23-L24-L25 -> 43451.91 | O27: =SUM(C27:N27) -> 438388.19
B28: Total Expenses | C28: =SUM(C23:C27) -> 137499.16 | D28: =SUM(D23:D27) -> 177096.43 | E28: =SUM(E23:E27) -> 146891.11 | F28: =SUM(F23:F27) -> 127499.77 | G28: =SUM(G23:G27) -> 143304.48 | H28: =SUM(H23:H27) -> 145630.11 | I28: =SUM(I23:I27) -> 137583.98 | J28: =SUM(J23:J27) -> 137733.14 | ... O28: =SUM(O23:O27) -> 1474463.6
B29: 2024 | C29: =+'2024byMonth'!C28 -> 119022.28 | D29: =+'2024byMonth'!D28 -> 174549.52 | E29: =+'2024byMonth'!E28 -> 121797.68 | F29: =+'2024byMonth'!F28 -> 139951.44 | G29: =+'2024byMonth'!G28 -> 138324.07 | H29: =+'2024byMonth'!H28 -> 140784.81 | I29: =+'2024byMonth'!I28 -> 125529.98 | J29: =+'2024byMonth'!J28 -> 138425.91 | ... N29: =+'2024byMonth'!N28 -> 174872.76 | O29: =SUM(C29:N29) -> 1677201.9
A30: Profit
B31: Net Profit Dollars | C31: =C20-C28 -> 14795.13 | D31: =D20-D28 -> 9988.88 | E31: =E20-E28 -> 29217.44 | F31: =F20-F28 -> 29794.32 | G31: =G20-G28 -> 22091.11 | H31: =H20-H28 -> -1175.48 | I31: =I20-I28 -> 15579 | J31: =J20-J28 -> 13798.32 | ... N31: =N20-N28 -> 0 | O31: =SUM(C31:N31) -> 196364.81
B32: 2024 | C32: =+'2024byMonth'!C31 -> -263.23 | D32: =+'2024byMonth'!D31 -> 4417.1 | E32: =+'2024byMonth'!E31 -> 25778.12 | F32: =+'2024byMonth'!F31 -> 8233.83 | G32: =+'2024byMonth'!G31 -> 5696.29 | H32: =+'2024byMonth'!H31 -> 7558.89 | I32: =+'2024byMonth'!I31 -> 2672.49 | J32: =+'2024byMonth'!J31 -> 5796.43 | ... N32: =+'2024byMonth'!N31 -> 1640.85 | O32: =SUM(C32:N32) -> 112298.22
A33: General Information
B34: # of Employees | C34: 8.5 | D34: 8.5 | E34: 8.5 | F34: 8.5 | G34: 8.5 | H34: 8.5 | I34: 8.5 | J34: 8.5 | K34: 7.5 | L34: 8.5
B35: # of Technical Employees | C35: 5.5 | D35: 5.5 | E35: 5.5 | F35: 5.5 | G35: 5.5 | H35: 5.5 | I35: 5.5 | J35: 5.5 | K35: 4.5 | L35: 5.5
B36: # of Seats Managed | C36: 546 | D36: 543 | E36: 542 | F36: 564 | G36: 585 | H36: 551 | I36: 548 | J36: 511 | K36: 509
B37: # of Manage Services Agreements | C37: 37 | D37: 36 | E37: 36 | F37: 37 | G37: 38 | H37: 38 | I37: 38 | J37: 38 | K37: 37
A39: Sales
B40: # of Telemarketing Dials | C40: 0 | D40: 0 | E40: 0 | F40: 0 | G40: 0 | H40: 0 | I40: 0 | J40: 0 | K40: 0 | L40: 0
B41: # of First Time Appointments (FTA) | C41: 0 | D41: 0 | E41: 0 | F41: 0 | G41: 2 | H41: 1 | J41: 2 | K41: 2 | L41: 3 | O41: =SUM(C41:N41) -> 10
B42: # of Prospects to Hit PBR | C42: 0 | D42: 0 | E42: 0 | F42: 0 | G42: 2 | H42: 0 | J42: 1 | K42: 0 | L42: 0 | O42: =SUM(C42:N42) -> 3
B43: # of New Agreements | C43: 0 | D43: 0 | E43: 0 | F43: 1 | G43: 2 | H43: 0 | I43: 0 | J43: 1 | K43: 1 | L43: 0 | O43: =SUM(C43:N43) -> 5
B44: New MRR | C44: 0 | D44: 0 | E44: 0 | F44: 813 | G44: =989+1100 -> 2089 | H44: 0 | I44: 0 | J44: 1605 | K44: 866 | O44: =SUM(C44:N44) -> 5373
B45: Lost MRR | C45: 0 | D45: 182.4 | E45: 0 | F45: 0 | G45: 2354 | H45: 0 | I45: 0 | J45: 11627 | K45: =415.73+415.35 -> 831.08 | O45: =SUM(C45:N45) -> 14994.48
B48: MSP turning point | C48: =(C15+C16)/(C23+C25+C27) -> 0.96646767 | D48: =(D15+D16)/(D23+D25+D27) -> 1.1933024 | E48: =(E15+E16)/(E23+E25+E27) -> 1.3123765 | F48: =(F15+F16)/(F23+F25+F27) -> 1.1549188 | G48: =(G15+G16)/(G23+G25+G27) -> 1.059074 | H48: =(H15+H16)/(H23+H25+H27) -> 1.1670152 | I48: =(I15+I16)/(I23+I25+I27) -> 1.1401367 | J48: =(J15+J16)/(J23+J25+J27) -> 1.1347971 | ... N48: =(N15+N16)/(N23+N25+N27) -> #DIV/0!
...

Sheet QBR 2025
A2: Quarterly Business Review 2025
I4: 2010
A6: Operations | C6: Q1 2025 | D6: Q2 2025 | E6: Q3 2025 | F6: Q4 2025 | G6: Total
B7: Category | C7: Amount | D7: Amount | E7: Amount | F7: Amount
B9: # of Reactive Tickets Created | C9: =+MonthlyINPUT!C9+MonthlyINPUT!D9+MonthlyINPUT!E9 -> 1081 | D9: =+MonthlyINPUT!F9+MonthlyINPUT!G9+MonthlyINPUT!H9 -> 1241 | E9: =+MonthlyINPUT!I9+MonthlyINPUT!J9+MonthlyINPUT!K9 -> 1080 | F9: =+MonthlyINPUT!L9+MonthlyINPUT!M9+MonthlyINPUT!N9 -> 361 | G9: =+C9+D9+E9+F9 -> 3763
B10: # of Reactive Tickets Closed | C10: =+MonthlyINPUT!C10+MonthlyINPUT!D10+MonthlyINPUT!E10 -> 1080 | D10: =+MonthlyINPUT!F10+MonthlyINPUT!G10+MonthlyINPUT!H10 -> 1231 | E10: =+MonthlyINPUT!I10+MonthlyINPUT!J10+MonthlyINPUT!K10 -> 1086 | F10: =+MonthlyINPUT!L10+MonthlyINPUT!M10+MonthlyINPUT!N10 -> 354 | G10: =+C10+D10+E10+F10 -> 3751
B11: Total Time on Reactive Tickets | C11: =+MonthlyINPUT!C11+MonthlyINPUT!D11+MonthlyINPUT!E11 -> 452.2 | D11: =+MonthlyINPUT!F11+MonthlyINPUT!G11+MonthlyINPUT!H11 -> 400.22 | E11: =+MonthlyINPUT!I11+MonthlyINPUT!J11+MonthlyINPUT!K11 -> 0 | F11: =+MonthlyINPUT!L11+MonthlyINPUT!M11+MonthlyINPUT!N11 -> 0 | G11: =+C11+D11+E11+F11 -> 852.42
B12: # of Endpoints Managed | C12: =+(MonthlyINPUT!C12+MonthlyINPUT!D12+MonthlyINPUT!E12)/3 -> 594 | D12: =+(MonthlyINPUT!F12+MonthlyINPUT!G12+MonthlyINPUT!H12)/3 -> 618 | E12: =+(MonthlyINPUT!I12+MonthlyINPUT!J12+MonthlyINPUT!K12)/3 -> 571.66667 | F12: =+(MonthlyINPUT!L12+MonthlyINPUT!M12+MonthlyINPUT!N12)/3 -> 384.66667 | G12: =+C12+D12+E12+F12 -> 2168.3333
A14: Revenue
B15: Non-recurring Revenue (NRR) | C15: =+MonthlyINPUT!C15+MonthlyINPUT!D15+MonthlyINPUT!E15 -> 32278.81 | D15: =+MonthlyINPUT!F15+MonthlyINPUT!G15+MonthlyINPUT!H15 -> 9352.11 | E15: =+MonthlyINPUT!I15+MonthlyINPUT!J15+MonthlyINPUT!K15 -> 28080.25 | F15: =+MonthlyINPUT!L15+MonthlyINPUT!M15+MonthlyINPUT!N15 -> 21264 | G15: =+C15+D15+E15+F15 -> 90975.17
B16: Monthly Recurring Revenue (MRR) | C16: =+MonthlyINPUT!C16+MonthlyINPUT!D16+MonthlyINPUT!E16 -> 329959.56 | D16: =+MonthlyINPUT!F16+MonthlyINPUT!G16+MonthlyINPUT!H16 -> 342826.86 | E16: =+MonthlyINPUT!I16+MonthlyINPUT!J16+MonthlyINPUT!K16 -> 327743.71 | F16: =+MonthlyINPUT!L16+MonthlyINPUT!M16+MonthlyINPUT!N16 -> 109227.29 | G16: =+C16+D16+E16+F16 -> 1109757.4
B17: Other Recurring Revenue (ORR) | C17: =+MonthlyINPUT!C17+MonthlyINPUT!D17+MonthlyINPUT!E17 -> 106999.8 | D17: =+MonthlyINPUT!F17+MonthlyINPUT!G17+MonthlyINPUT!H17 -> 82858.1 | E17: =+MonthlyINPUT!I17+MonthlyINPUT!J17+MonthlyINPUT!K17 -> 57183.53 | F17: =+MonthlyINPUT!L17+MonthlyINPUT!M17+MonthlyINPUT!N17 -> 12346.64 | G17: =+C17+D17+E17+F17 -> 259388.07
B18: Product Sales | C18: =+MonthlyINPUT!C18+MonthlyINPUT!D18+MonthlyINPUT!E18 -> 46249.98 | D18: =+MonthlyINPUT!F18+MonthlyINPUT!G18+MonthlyINPUT!H18 -> 32107.24 | E18: =+MonthlyINPUT!I18+MonthlyINPUT!J18+MonthlyINPUT!K18 -> 94202.06 | F18: =+MonthlyINPUT!L18+MonthlyINPUT!M18+MonthlyINPUT!N18 -> 38148.49 | G18: =+C18+D18+E18+F18 -> 210707.77
B19: Miscellaneous revenue | C19: =+MonthlyINPUT!C19+MonthlyINPUT!D19+MonthlyINPUT!E19 -> 0 | D19: =+MonthlyINPUT!F19+MonthlyINPUT!G19+MonthlyINPUT!H19 -> 0 | E19: =+MonthlyINPUT!I19+MonthlyINPUT!J19+MonthlyINPUT!K19 -> 0 | F19: =+MonthlyINPUT!L19+MonthlyINPUT!M19+MonthlyINPUT!N19 -> 0 | G19: =+C19+D19+E19+F19 -> 0
B20: Total Revenue | C20: =SUM(C15:C19) -> 515488.15 | D20: =SUM(D15:D19) -> 467144.31 | E20: =SUM(E15:E19) -> 507209.55 | F20: =SUM(F15:F19) -> 180986.42 | G20: =+C20+D20+E20+F20 -> 1670828.4
A22: Expenses
B23: Employee Expense | C23: =+MonthlyINPUT!C23+MonthlyINPUT!D23+MonthlyINPUT!E23 -> 115610.18 | D23: =+MonthlyINPUT!F23+MonthlyINPUT!G23+MonthlyINPUT!H23 -> 111520.56 | E23: =+MonthlyINPUT!I23+MonthlyINPUT!J23+MonthlyINPUT!K23 -> 113087.03 | F23: =+MonthlyINPUT!L23+MonthlyINPUT!M23+MonthlyINPUT!N23 -> 37788.453 | G23: =+C23+D23+E23+F23 -> 378006.22
B24: Owner Comp to pay QTR est taxes | C24: =+MonthlyINPUT!C24+MonthlyINPUT!D24+MonthlyINPUT!E24 -> 27700 | D24: =+MonthlyINPUT!F24+MonthlyINPUT!G24+MonthlyINPUT!H24 -> 41000 | E24: =+MonthlyINPUT!I24+MonthlyINPUT!J24+MonthlyINPUT!K24 -> 36000 | F24: =+MonthlyINPUT!L24+MonthlyINPUT!M24+MonthlyINPUT!N24 -> 12000 | G24: =+C24+D24+E24+F24 -> 116700
B25: Owners Compensation | C25: =+MonthlyINPUT!C25+MonthlyINPUT!D25+MonthlyINPUT!E25 -> 67765.4 | D25: =+MonthlyINPUT!F25+MonthlyINPUT!G25+MonthlyINPUT!H25 -> 67765.4 | E25: =+MonthlyINPUT!I25+MonthlyINPUT!J25+MonthlyINPUT!K25 -> 67765.4 | F25: =+MonthlyINPUT!L25+MonthlyINPUT!M25+MonthlyINPUT!N25 -> 22588.467 | G25: =+C25+D25+E25+F25 -> 225884.67
B26: Product Cost of Goods Sold (COGS) | C26: =+MonthlyINPUT!C26+MonthlyINPUT!D26+MonthlyINPUT!E26 -> 119202.84 | D26: =+MonthlyINPUT!F26+MonthlyINPUT!G26+MonthlyINPUT!H26 -> 62122.09 | E26: =+MonthlyINPUT!I26+MonthlyINPUT!J26+MonthlyINPUT!K26 -> 100474.62 | F26: =+MonthlyINPUT!L26+MonthlyINPUT!M26+MonthlyINPUT!N26 -> 33684.99 | G26: =+C26+D26+E26+F26 -> 315484.54
B27: All Other Expenses | C27: =+MonthlyINPUT!C27+MonthlyINPUT!D27+MonthlyINPUT!E27 -> 131208.28 | D27: =+MonthlyINPUT!F27+MonthlyINPUT!G27+MonthlyINPUT!H27 -> 134026.31 | E27: =+MonthlyINPUT!I27+MonthlyINPUT!J27+MonthlyINPUT!K27 -> 129701.69 | F27: =+MonthlyINPUT!L27+MonthlyINPUT!M27+MonthlyINPUT!N27 -> 43451.91 | G27: =+C27+D27+E27+F27 -> 438388.19
B28: Total Expenses | C28: =SUM(C23:C27) -> 461486.7 | D28: =SUM(D23:D27) -> 416434.36 | E28: =SUM(E23:E27) -> 447028.74 | F28: =SUM(F23:F27) -> 149513.82 | G28: =+C28+D28+E28+F28 -> 1474463.6
A30: Profit
B31: Net Profit Dollars | C31: =C20-C28 -> 54001.45 | D31: =D20-D28 -> 50709.95 | E31: =E20-E28 -> 60180.81 | F31: =F20-F28 -> 31472.6 | G31: =+C31+D31+E31+F31 -> 196364.81
A33: General Information
B34: # of Employees | C34: =+(MonthlyINPUT!C34+MonthlyINPUT!D34+MonthlyINPUT!E34)/3 -> 8.5 | D34: =+(MonthlyINPUT!F34+MonthlyINPUT!G34+MonthlyINPUT!H34)/3 -> 8.5 | E34: =+(MonthlyINPUT!I34+MonthlyINPUT!J34+MonthlyINPUT!K34)/3 -> 8.1666667 | F34: =+(MonthlyINPUT!L34+MonthlyINPUT!M34+MonthlyINPUT!N34)/3 -> 2.8333333
B35: # of Technical Employees | C35: =+(MonthlyINPUT!C35+MonthlyINPUT!D35+MonthlyINPUT!E35)/3 -> 5.5 | D35: =+(MonthlyINPUT!F35+MonthlyINPUT!G35+MonthlyINPUT!H35)/3 -> 5.5 | E35: =+(MonthlyINPUT!I35+MonthlyINPUT!J35+MonthlyINPUT!K35)/3 -> 5.1666667 | F35: =+(MonthlyINPUT!L35+MonthlyINPUT!M35+MonthlyINPUT!N35)/3 -> 1.8333333
B36: # of Seats Managed | C36: =+(MonthlyINPUT!C36+MonthlyINPUT!D36+MonthlyINPUT!E36)/3 -> 543.66667 | D36: =+(MonthlyINPUT!F36+MonthlyINPUT!G36+MonthlyINPUT!H36)/3 -> 566.66667 | E36: =+(MonthlyINPUT!I36+MonthlyINPUT!J36+MonthlyINPUT!K36)/3 -> 522.66667 | F36: =+(MonthlyINPUT!L36+MonthlyINPUT!M36+MonthlyINPUT!N36)/3 -> 0
B37: # of Manage Services Agreements | C37: =+(MonthlyINPUT!C37+MonthlyINPUT!D37+MonthlyINPUT!E37)/3 -> 36.333333 | D37: =+(MonthlyINPUT!F37+MonthlyINPUT!G37+MonthlyINPUT!H37)/3 -> 37.666667 | E37: =+(MonthlyINPUT!I37+MonthlyINPUT!J37+MonthlyINPUT!K37)/3 -> 37.666667 | F37: =+(MonthlyINPUT!L37+MonthlyINPUT!M37+MonthlyINPUT!N37)/3 -> 0
A39: Sales
B40: # of Telemarketing Dials | C40: =+MonthlyINPUT!C40+MonthlyINPUT!D40+MonthlyINPUT!E40 -> 0 | D40: =+MonthlyINPUT!F40+MonthlyINPUT!G40+MonthlyINPUT!H40 -> 0 | E40: =+MonthlyINPUT!I40+MonthlyINPUT!J40+MonthlyINPUT!K40 -> 0 | F40: =+MonthlyINPUT!L40+MonthlyINPUT!M40+MonthlyINPUT!N40 -> 0 | G40: =+C40+D40+E40+F40 -> 0
B41: # of First Time Appointments (FTA) | C41: =+MonthlyINPUT!C41+MonthlyINPUT!D41+MonthlyINPUT!E41 -> 0 | D41: =+MonthlyINPUT!F41+MonthlyINPUT!G41+MonthlyINPUT!H41 -> 3 | E41: =+MonthlyINPUT!I41+MonthlyINPUT!J41+MonthlyINPUT!K41 -> 4 | F41: =+MonthlyINPUT!L41+MonthlyINPUT!M41+MonthlyINPUT!N41 -> 3 | G41: =+C41+D41+E41+F41 -> 10
B42: # of Prospects to Hit PBR | C42: =+MonthlyINPUT!C42+MonthlyINPUT!D42+MonthlyINPUT!E42 -> 0 | D42: =+MonthlyINPUT!F42+MonthlyINPUT!G42+MonthlyINPUT!H42 -> 2 | E42: =+MonthlyINPUT!I42+MonthlyINPUT!J42+MonthlyINPUT!K42 -> 1 | F42: =+MonthlyINPUT!L42+MonthlyINPUT!M42+MonthlyINPUT!N42 -> 0 | G42: =+C42+D42+E42+F42 -> 3
B43: # of New Agreements | C43: =+MonthlyINPUT!C43+MonthlyINPUT!D43+MonthlyINPUT!E43 -> 0 | D43: =+MonthlyINPUT!F43+MonthlyINPUT!G43+MonthlyINPUT!H43 -> 3 | E43: =+MonthlyINPUT!I43+MonthlyINPUT!J43+MonthlyINPUT!K43 -> 2 | F43: =+MonthlyINPUT!L43+MonthlyINPUT!M43+MonthlyINPUT!N43 -> 0 | G43: =+C43+D43+E43+F43 -> 5
B44: New MRR | C44: =+MonthlyINPUT!C44+MonthlyINPUT!D44+MonthlyINPUT!E44 -> 0 | D44: =+MonthlyINPUT!F44+MonthlyINPUT!G44+MonthlyINPUT!H44 -> 2902 | E44: =+MonthlyINPUT!I44+MonthlyINPUT!J44+MonthlyINPUT!K44 -> 2471 | F44: =+MonthlyINPUT!L44+MonthlyINPUT!M44+MonthlyINPUT!N44 -> 0 | G44: =+C44+D44+E44+F44 -> 5373
B45: Lost MRR | C45: =+MonthlyINPUT!C45+MonthlyINPUT!D45+MonthlyINPUT!E45 -> 182.4 | D45: =+MonthlyINPUT!F45+MonthlyINPUT!G45+MonthlyINPUT!H45 -> 2354 | E45: =+MonthlyINPUT!I45+MonthlyINPUT!J45+MonthlyINPUT!K45 -> 12458.08 | F45: =+MonthlyINPUT!L45+MonthlyINPUT!M45+MonthlyINPUT!N45 -> 0 | G45: =+C45+D45+E45+F45 -> 14994.48

Sheet QBRcompare
A2: Quarterly Business Review Comparison 2025 vs 2024
Y4: 2010
C5: Quarter 1 | G5: Quarter 2 | K5: Quarter 3 | O5: Quarter 4 | S5: YTD
A6: Operations | C6: 2025 | D6: 2024 | E6: change | F6: % | G6: 2025 | H6: 2024 | I6: change | J6: % | K6: 2025 | L6: 2024 | M6: change | N6: % | O6: 2025 | P6: 2024 | Q6: Change | R6: % change | S6: 2025 | T6: 2024 | U6: change | V6: %
B7: Category
B9: # of Reactive Tickets Created | C9: =+'QBR 2025'!C9 -> 1081 | D9: =+'QBR 2024'!C9 -> 0 | E9: =+C9-D9 -> 1081 | F9: =IFERROR(+E9/D9,"--") -> -- | G9: =+'QBR 2025'!D9 -> 1241 | H9: =+'QBR 2024'!D9 -> 0 | I9: =+G9-H9 -> 1241 | J9: =IFERROR(+I9/H9,"--") -> -- | K9: =+'QBR 2025'!E9 -> 1080 | L9: =+'QBR 2024'!E9 -> 0 | M9: =+K9-L9 -> 1080 | N9: =IFERROR(+M9/L9,"--") -> -- | O9: =+'QBR 2025'!F9 -> 361 | P9: =+'QBR 2024'!F9 -> 0 | Q9: =+O9-P9 -> 361 | R9: =IFERROR(+Q9/P9,"--") -> -- | S9: =+C9+G9+K9+O9 -> 3763 | T9: =+D9+H9+L9+P9 -> 0 | U9: =+S9-T9 -> 3763 | V9: =IFERROR(+U9/T9,"--") -> --
B10: # of Reactive Tickets Closed | C10: =+'QBR 2025'!C10 -> 1080 | D10: =+'QBR 2024'!C10 -> 0 | E10: =+C10-D10 -> 1080 | F10: =IFERROR(+E10/D10,"--") -> -- | G10: =+'QBR 2025'!D10 -> 1231 | H10: =+'QBR 2024'!D10 -> 0 | I10: =+G10-H10 -> 1231 | J10: =IFERROR(+I10/H10,"--") -> -- | K10: =+'QBR 2025'!E10 -> 1086 | L10: =+'QBR 2024'!E10 -> 0 | M10: =+K10-L10 -> 1086 | N10: =IFERROR(+M10/L10,"--") -> -- | O10: =+'QBR 2025'!F10 -> 354 | P10: =+'QBR 2024'!F10 -> 0 | Q10: =+O10-P10 -> 354 | R10: =IFERROR(+Q10/P10,"--") -> -- | S10: =+C10+G10+K10+O10 -> 3751 | T10: =+D10+H10+L10+P10 -> 0 | U10: =+S10-T10 -> 3751 | V10: =IFERROR(+U10/T10,"--") -> --
B11: Total Time on Reactive Tickets | C11: =+'QBR 2025'!C11 -> 452.2 | D11: =+'QBR 2024'!C11 -> 0 | E11: =+C11-D11 -> 452.2 | F11: =IFERROR(+E11/D11,"--") -> -- | G11: =+'QBR 2025'!D11 -> 400.22 | H11: =+'QBR 2024'!D11 -> 0 | I11: =+G11-H11 -> 400.22 | J11: =IFERROR(+I11/H11,"--") -> -- | K11: =+'QBR 2025'!E11 -> 0 | L11: =+'QBR 2024'!E11 -> 0 | M11: =+K11-L11 -> 0 | N11: =IFERROR(+M11/L11,"--") -> -- | O11: =+'QBR 2025'!F11 -> 0 | P11: =+'QBR 2024'!F11 -> 0 | Q11: =+O11-P11 -> 0 | R11: =IFERROR(+Q11/P11,"--") -> -- | S11: =+C11+G11+K11+O11 -> 852.42 | T11: =+D11+H11+L11+P11 -> 0 | U11: =+S11-T11 -> 852.42 | V11: =IFERROR(+U11/T11,"--") -> --
B12: # of Endpoints Managed | C12: =+'QBR 2025'!C12 -> 594 | D12: =+'QBR 2024'!C12 -> 528.66667 | E12: =+C12-D12 -> 65.333333 | F12: =IFERROR(+E12/D12,"--") -> 0.12358134 | G12: =+'QBR 2025'!D12 -> 618 | H12: =+'QBR 2024'!D12 -> 553.33333 | I12: =+G12-H12 -> 64.666667 | J12: =IFERROR(+I12/H12,"--") -> 0.11686747 | K12: =+'QBR 2025'!E12 -> 571.66667 | L12: =+'QBR 2024'!E12 -> 561.66667 | M12: =+K12-L12 -> 10 | N12: =IFERROR(+M12/L12,"--") -> 0.017804154 | O12: =+'QBR 2025'!F12 -> 384.66667 | P12: =+'QBR 2024'!F12 -> 586.33333 | Q12: =+O12-P12 -> -201.66667 | R12: =IFERROR(+Q12/P12,"--") -> -0.34394542 | S12: =+C12+G12+K12+O12 -> 2168.3333 | T12: =+D12+H12+L12+P12 -> 2230 | U12: =+S12-T12 -> -61.666667 | V12: =IFERROR(+U12/T12,"--") -> -0.027653214
A14: Revenue
B15: Non-recurring Revenue (NRR) | C15: =+'QBR 2025'!C15 -> 32278.81 | D15: =+'QBR 2024'!C15 -> 26526.25 | E15: =+C15-D15 -> 5752.56 | F15: =IFERROR(+E15/D15,"--") -> 0.21686292 | G15: =+'QBR 2025'!D15 -> 9352.11 | H15: =+'QBR 2024'!D15 -> 19478.25 | I15: =+G15-H15 -> -10126.14 | J15: =IFERROR(+I15/H15,"--") -> -0.51986908 | K15: =+'QBR 2025'!E15 -> 28080.25 | L15: =+'QBR 2024'!E15 -> 14203 | M15: =+K15-L15 -> 13877.25 | N15: =IFERROR(+M15/L15,"--") -> 0.9770647 | O15: =+'QBR 2025'!F15 -> 21264 | P15: =+'QBR 2024'!F15 -> 26548 | Q15: =+O15-P15 -> -5284 | R15: =IFERROR(+Q15/P15,"--") -> -0.19903571 | S15: =+C15+G15+K15+O15 -> 90975.17 | T15: =+D15+H15+L15+P15 -> 86755.5 | U15: =+S15-T15 -> 4219.67 | V15: =IFERROR(+U15/T15,"--") -> 0.048638645
B16: Monthly Recurring Revenue (MRR) | C16: =+'QBR 2025'!C16 -> 329959.56 | D16: =+'QBR 2024'!C16 -> 287788.4 | E16: =+C16-D16 -> 42171.16 | F16: =IFERROR(+E16/D16,"--") -> 0.1465353 | G16: =+'QBR 2025'!D16 -> 342826.86 | H16: =+'QBR 2024'!D16 -> 304595.67 | I16: =+G16-H16 -> 38231.19 | J16: =IFERROR(+I16/H16,"--") -> 0.12551456 | K16: =+'QBR 2025'!E16 -> 327743.71 | L16: =+'QBR 2024'!E16 -> 310265.96 | M16: =+K16-L16 -> 17477.75 | N16: =IFERROR(+M16/L16,"--") -> 0.05633151 | O16: =+'QBR 2025'!F16 -> 109227.29 | P16: =+'QBR 2024'!F16 -> 320327.52 | Q16: =+O16-P16 -> -211100.23 | R16: =IFERROR(+Q16/P16,"--") -> -0.65901372 | S16: =+C16+G16+K16+O16 -> 1109757.4 | T16: =+D16+H16+L16+P16 -> 1222977.6 | U16: =+S16-T16 -> -113220.13 | V16: =IFERROR(+U16/T16,"--") -> -0.092577439
B17: Other Recurring Revenue (ORR) | C17: =+'QBR 2025'!C17 -> 106999.8 | D17: =+'QBR 2024'!C17 -> 95446.78 | E17: =+C17-D17 -> 11553.02 | F17: =IFERROR(+E17/D17,"--") -> 0.12104149 | G17: =+'QBR 2025'!D17 -> 82858.1 | H17: =+'QBR 2024'!D17 -> 50566.36 | I17: =+G17-H17 -> 32291.74 | J17: =IFERROR(+I17/H17,"--") -> 0.63860124 | K17: =+'QBR 2025'!E17 -> 57183.53 | L17: =+'QBR 2024'!E17 -> 58067.09 | M17: =+K17-L17 -> -883.56 | N17: =IFERROR(+M17/L17,"--") -> -0.015216192 | O17: =+'QBR 2025'!F17 -> 12346.64 | P17: =+'QBR 2024'!F17 -> 82498.43 | Q17: =+O17-P17 -> -70151.79 | R17: =IFERROR(+Q17/P17,"--") -> -0.85034091 | S17: =+C17+G17+K17+O17 -> 259388.07 | T17: =+D17+H17+L17+P17 -> 286578.66 | U17: =+S17-T17 -> -27190.59 | V17: =IFERROR(+U17/T17,"--") -> -0.094880024
B18: Product Sales | C18: =+'QBR 2025'!C18 -> 46249.98 | D18: =+'QBR 2024'!C18 -> 35540.04 | E18: =+C18-D18 -> 10709.94 | F18: =IFERROR(+E18/D18,"--") -> 0.30134856 | G18: =+'QBR 2025'!D18 -> 32107.24 | H18: =+'QBR 2024'!D18 -> 65909.05 | I18: =+G18-H18 -> -33801.81 | J18: =IFERROR(+I18/H18,"--") -> -0.51285537 | K18: =+'QBR 2025'!E18 -> 94202.06 | L18: =+'QBR 2024'!E18 -> 34040.58 | M18: =+K18-L18 -> 60161.48 | N18: =IFERROR(+M18/L18,"--") -> 1.7673459 | O18: =+'QBR 2025'!F18 -> 38148.49 | P18: =+'QBR 2024'!F18 -> 57698.77 | Q18: =+O18-P18 -> -19550.28 | R18: =IFERROR(+Q18/P18,"--") -> -0.33883357 | S18: =+C18+G18+K18+O18 -> 210707.77 | T18: =+D18+H18+L18+P18 -> 193188.44 | U18: =+S18-T18 -> 17519.33 | V18: =IFERROR(+U18/T18,"--") -> 0.090685188
B19: Miscellaneous revenue | C19: =+'QBR 2025'!C19 -> 0 | D19: =+'QBR 2024'!C19 -> 0 | E19: =+C19-D19 -> 0 | F19: =IFERROR(+E19/D19,"--") -> -- | G19: =+'QBR 2025'!D19 -> 0 | H19: =+'QBR 2024'!D19 -> 0 | I19: =+G19-H19 -> 0 | J19: =IFERROR(+I19/H19,"--") -> -- | K19: =+'QBR 2025'!E19 -> 0 | L19: =+'QBR 2024'!E19 -> 0 | M19: =+K19-L19 -> 0 | N19: =IFERROR(+M19/L19,"--") -> -- | O19: =+'QBR 2025'!F19 -> 0 | P19: =+'QBR 2024'!F19 -> 0 | Q19: =+O19-P19 -> 0 | R19: =IFERROR(+Q19/P19,"--") -> -- | S19: =+C19+G19+K19+O19 -> 0 | T19: =+D19+H19+L19+P19 -> 0 | U19: =+S19-T19 -> 0 | V19: =IFERROR(+U19/T19,"--") -> --
B20: Total Revenue | C20: =SUM(C15:C19) -> 515488.15 | D20: =SUM(D15:D19) -> 445301.47 | E20: =+C20-D20 -> 70186.68 | F20: =IFERROR(+E20/D20,"--") -> 0.1576161 | G20: =SUM(G15:G19) -> 467144.31 | H20: =SUM(H15:H19) -> 440549.33 | I20: =+G20-H20 -> 26594.98 | J20: =IFERROR(+I20/H20,"--") -> 0.060367769 | K20: =SUM(K15:K19) -> 507209.55 | L20: =SUM(L15:L19) -> 416576.63 | M20: =+K20-L20 -> 90632.92 | N20: =IFERROR(+M20/L20,"--") -> 0.21756602 | O20: =SUM(O15:O19) -> 180986.42 | P20: =SUM(P15:P19) -> 487072.72 | Q20: =+O20-P20 -> -306086.3 | R20: =IFERROR(+Q20/P20,"--") -> -0.62842013 | S20: =SUM(S15:S19) -> 1670828.4 | T20: =SUM(T15:T19) -> 1789500.1 | U20: =+S20-T20 -> -118671.72 | V20: =IFERROR(+U20/T20,"--") -> -0.066315569
A22: Expenses
B23: Employee Expense | C23: =+'QBR 2025'!C23 -> 115610.18 | D23: =+'QBR 2024'!C23 -> 113025.47 | E23: =+C23-D23 -> 2584.71 | F23: =IFERROR(+E23/D23,"--") -> 0.022868385 | G23: =+'QBR 2025'!D23 -> 111520.56 | H23: =+'QBR 2024'!D23 -> 114620.05 | I23: =+G23-H23 -> -3099.49 | J23: =IFERROR(+I23/H23,"--") -> -0.027041429 | K23: =+'QBR 2025'!E23 -> 113087.03 | L23: =+'QBR 2024'!E23 -> 114209.4 | M23: =+K23-L23 -> -1122.37 | N23: =IFERROR(+M23/L23,"--") -> -0.0098272997 | O23: =+'QBR 2025'!F23 -> 37788.453 | P23: =+'QBR 2024'!F23 -> 116021.63 | Q23: =+O23-P23 -> -78233.177 | R23: =IFERROR(+Q23/P23,"--") -> -0.6742982 | S23: =+C23+G23+K23+O23 -> 378006.22 | T23: =+D23+H23+L23+P23 -> 457876.55 | U23: =+S23-T23 -> -79870.327 | V23: =IFERROR(+U23/T23,"--") -> -0.17443638
B24: Owners Compensation | C24: =+'QBR 2025'!C25 -> 67765.4 | D24: =+'QBR 2024'!C24 -> 15000 | E24: =+C24-D24 -> 52765.4 | F24: =IFERROR(+E24/D24,"--") -> 3.5176933 | G24: =+'QBR 2025'!D25 -> 67765.4 | H24: =+'QBR 2024'!D24 -> 15000 | I24: =+G24-H24 -> 52765.4 | J24: =IFERROR(+I24/H24,"--") -> 3.5176933 | K24: =+'QBR 2025'!E25 -> 67765.4 | L24: =+'QBR 2024'!E24 -> 15000 | M24: =+K24-L24 -> 52765.4 | N24: =IFERROR(+M24/L24,"--") -> 3.5176933 | O24: =+'QBR 2025'!F25 -> 22588.467 | P24: =+'QBR 2024'!F24 -> 15000 | Q24: =+O24-P24 -> 7588.4667 | R24: =IFERROR(+Q24/P24,"--") -> 0.50589778 | S24: =+C24+G24+K24+O24 -> 225884.67 | T24: =+D24+H24+L24+P24 -> 60000 | U24: =+S24-T24 -> 165884.67 | V24: =IFERROR(+U24/T24,"--") -> 2.7647444
B25: Product Cost of Goods Sold (COGS) | C25: =+'QBR 2025'!C26 -> 119202.84 | D25: =+'QBR 2024'!C26 -> 98897.94 | E25: =+C25-D25 -> 20304.9 | F25: =IFERROR(+E25/D25,"--") -> 0.20531166 | G25: =+'QBR 2025'!D26 -> 62122.09 | H25: =+'QBR 2024'!D26 -> 77212.01 | I25: =+G25-H25 -> -15089.92 | J25: =IFERROR(+I25/H25,"--") -> -0.19543488 | K25: =+'QBR 2025'!E26 -> 100474.62 | L25: =+'QBR 2024'!E26 -> 61472.68 | M25: =+K25-L25 -> 39001.94 | N25: =IFERROR(+M25/L25,"--") -> 0.63445973 | O25: =+'QBR 2025'!F26 -> 33684.99 | P25: =+'QBR 2024'!F26 -> 88869.55 | Q25: =+O25-P25 -> -55184.56 | R25: =IFERROR(+Q25/P25,"--") -> -0.6209614 | S25: =+C25+G25+K25+O25 -> 315484.54 | T25: =+D25+H25+L25+P25 -> 326452.18 | U25: =+S25-T25 -> -10967.64 | V25: =IFERROR(+U25/T25,"--") -> -0.033596467
B26: All Other Expenses | C26: =+'QBR 2025'!C27 -> 131208.28 | D26: =+'QBR 2024'!C27 -> 127171.07 | E26: =+C26-D26 -> 4037.21 | F26: =IFERROR(+E26/D26,"--") -> 0.031746293 | G26: =+'QBR 2025'!D27 -> 134026.31 | H26: =+'QBR 2024'!D27 -> 150953.26 | I26: =+G26-H26 -> -16926.95 | J26: =IFERROR(+I26/H26,"--") -> -0.11213372 | K26: =+'QBR 2025'!E27 -> 129701.69 | L26: =+'QBR 2024'!E27 -> 137468.74 | M26: =+K26-L26 -> -7767.05 | N26: =IFERROR(+M26/L26,"--") -> -0.056500481 | O26: =+'QBR 2025'!F27 -> 43451.91 | P26: =+'QBR 2024'!F27 -> 146180.13 | Q26: =+O26-P26 -> -102728.22 | R26: =IFERROR(+Q26/P26,"--") -> -0.70275091 | S26: =+C26+G26+K26+O26 -> 438388.19 | T26: =+D26+H26+L26+P26 -> 561773.2 | U26: =+S26-T26 -> -123385.01 | V26: =IFERROR(+U26/T26,"--") -> -0.21963492
B27: Total Expenses | C27: =SUM(C23:C26) -> 433786.7 | D27: =SUM(D23:D26) -> 354094.48 | E27: =+C27-D27 -> 79692.22 | F27: =IFERROR(+E27/D27,"--") -> 0.2250592 | G27: =SUM(G23:G26) -> 375434.36 | H27: =SUM(H23:H26) -> 357785.32 | I27: =+G27-H27 -> 17649.04 | J27: =IFERROR(+I27/H27,"--") -> 0.049328575 | K27: =SUM(K23:K26) -> 411028.74 | L27: =SUM(L23:L26) -> 328150.82 | M27: =+K27-L27 -> 82877.92 | N27: =IFERROR(+M27/L27,"--") -> 0.25256045 | O27: =SUM(O23:O26) -> 137513.82 | P27: =SUM(P23:P26) -> 366071.31 | Q27: =+O27-P27 -> -228557.49 | R27: =IFERROR(+Q27/P27,"--") -> -0.62435237 | S27: =SUM(S23:S26) -> 1357763.6 | T27: =SUM(T23:T26) -> 1406101.9 | U27: =+S27-T27 -> -48338.31 | V27: =IFERROR(+U27/T27,"--") -> -0.034377529
A29: Profit
B30: Net Profit Dollars | C30: =C20-C27 -> 81701.45 | D30: =D20-D27 -> 91206.99 | E30: =+C30-D30 -> -9505.54 | F30: =IFERROR(+E30/D30,"--") -> -0.10421942 | G30: =G20-G27 -> 91709.95 | H30: =H20-H27 -> 82764.01 | I30: =+G30-H30 -> 8945.94 | J30: =IFERROR(+I30/H30,"--") -> 0.10808974 | K30: =K20-K27 -> 96180.81 | L30: =L20-L27 -> 88425.81 | M30: =+K30-L30 -> 7755 | N30: =IFERROR(+M30/L30,"--") -> 0.087700639 | O30: =O20-O27 -> 43472.6 | P30: =P20-P27 -> 121001.41 | Q30: =+O30-P30 -> -77528.81 | R30: =IFERROR(+Q30/P30,"--") -> -0.6407265 | S30: =S20-S27 -> 313064.81 | T30: =T20-T27 -> 383398.22 | U30: =+S30-T30 -> -70333.41 | V30: =IFERROR(+U30/T30,"--") -> -0.18344741
A32: General Information
B33: # of Employees | C33: =+'QBR 2025'!C34 -> 8.5 | D33: =+'QBR 2024'!C34 -> 8.5 | E33: =+C33-D33 -> 0 | F33: =IFERROR(+E33/D33,"--") -> 0 | G33: =+'QBR 2025'!D34 -> 8.5 | H33: =+'QBR 2024'!D34 -> 8.5 | I33: =+G33-H33 -> 0 | J33: =IFERROR(+I33/H33,"--") -> 0 | K33: =+'QBR 2025'!E34 -> 8.1666667 | L33: =+'QBR 2024'!E34 -> 8.5 | M33: =+K33-L33 -> -0.33333333 | N33: =IFERROR(+M33/L33,"--") -> -0.039215686 | O33: =+'QBR 2025'!F34 -> 2.8333333 | P33: =+'QBR 2024'!F34 -> 8.5 | Q33: =+O33-P33 -> -5.6666667 | R33: =IFERROR(+Q33/P33,"--") -> -0.66666667
B34: # of Technical Employees | C34: =+'QBR 2025'!C35 -> 5.5 | D34: =+'QBR 2024'!C35 -> 5.5 | E34: =+C34-D34 -> 0 | F34: =IFERROR(+E34/D34,"--") -> 0 | G34: =+'QBR 2025'!D35 -> 5.5 | H34: =+'QBR 2024'!D35 -> 5.5 | I34: =+G34-H34 -> 0 | J34: =IFERROR(+I34/H34,"--") -> 0 | K34: =+'QBR 2025'!E35 -> 5.1666667 | L34: =+'QBR 2024'!E35 -> 5.5 | M34: =+K34-L34 -> -0.33333333 | N34: =IFERROR(+M34/L34,"--") -> -0.060606061 | O34: =+'QBR 2025'!F35 -> 1.8333333 | P34: =+'QBR 2024'!F35 -> 5.5 | Q34: =+O34-P34 -> -3.6666667 | R34: =IFERROR(+Q34/P34,"--") -> -0.66666667
B35: # of Seats Managed | C35: =+'QBR 2025'!C36 -> 543.66667 | D35: =+'QBR 2024'!C36 -> 477.33333 | E35: =+C35-D35 -> 66.333333 | F35: =IFERROR(+E35/D35,"--") -> 0.13896648 | G35: =+'QBR 2025'!D36 -> 566.66667 | H35: =+'QBR 2024'!D36 -> 502.66667 | I35: =+G35-H35 -> 64 | J35: =IFERROR(+I35/H35,"--") -> 0.12732095 | K35: =+'QBR 2025'!E36 -> 522.66667 | L35: =+'QBR 2024'!E36 -> 512 | M35: =+K35-L35 -> 10.666667 | N35: =IFERROR(+M35/L35,"--") -> 0.020833333 | O35: =+'QBR 2025'!F36 -> 0 | P35: =+'QBR 2024'!F36 -> 536.66667 | Q35: =+O35-P35 -> -536.66667 | R35: =IFERROR(+Q35/P35,"--") -> -1
B36: # of Manage Services Agreements | C36: =+'QBR 2025'!C37 -> 36.333333 | D36: =+'QBR 2024'!C37 -> 34.333333 | E36: =+C36-D36 -> 2 | F36: =IFERROR(+E36/D36,"--") -> 0.058252427 | G36: =+'QBR 2025'!D37 -> 37.666667 | H36: =+'QBR 2024'!D37 -> 34.666667 | I36: =+G36-H36 -> 3 | J36: =IFERROR(+I36/H36,"--") -> 0.086538462 | K36: =+'QBR 2025'!E37 -> 37.666667 | L36: =+'QBR 2024'!E37 -> 35 | M36: =+K36-L36 -> 2.6666667 | N36: =IFERROR(+M36/L36,"--") -> 0.076190476 | O36: =+'QBR 2025'!F37 -> 0 | P36: =+'QBR 2024'!F37 -> 35 | Q36: =+O36-P36 -> -35 | R36: =IFERROR(+Q36/P36,"--") -> -1
A38: Sales
B39: # of Telemarketing Dials | C39: =+'QBR 2025'!C40 -> 0 | D39: =+'QBR 2024'!C40 -> 0 | E39: =+C39-D39 -> 0 | G39: =+'QBR 2025'!D40 -> 0 | H39: =+'QBR 2024'!D40 -> 0 | I39: =+G39-H39 -> 0 | K39: =+'QBR 2025'!E40 -> 0 | L39: =+'QBR 2024'!E40 -> 0 | M39: =+K39-L39 -> 0 | O39: =+'QBR 2025'!F40 -> 0 | P39: =+'QBR 2024'!F40 -> 0 | Q39: =+O39-P39 -> 0
B40: # of First Time Appointments (FTA) | C40: =+'QBR 2025'!C41 -> 0 | D40: =+'QBR 2024'!C41 -> 12 | E40: =+C40-D40 -> -12 | G40: =+'QBR 2025'!D41 -> 3 | H40: =+'QBR 2024'!D41 -> 4 | I40: =+G40-H40 -> -1 | K40: =+'QBR 2025'!E41 -> 4 | L40: =+'QBR 2024'!E41 -> 0 | M40: =+K40-L40 -> 4 | O40: =+'QBR 2025'!F41 -> 3 | P40: =+'QBR 2024'!F41 -> 2 | Q40: =+O40-P40 -> 1
B41: # of Prospects to Hit PBR | C41: =+'QBR 2025'!C42 -> 0 | D41: =+'QBR 2024'!C42 -> 0 | E41: =+C41-D41 -> 0 | G41: =+'QBR 2025'!D42 -> 2 | H41: =+'QBR 2024'!D42 -> 0 | I41: =+G41-H41 -> 2 | K41: =+'QBR 2025'!E42 -> 1 | L41: =+'QBR 2024'!E42 -> 0 | M41: =+K41-L41 -> 1 | O41: =+'QBR 2025'!F42 -> 0 | P41: =+'QBR 2024'!F42 -> 1 | Q41: =+O41-P41 -> -1
B42: # of New Agreements | C42: =+'QBR 2025'!C43 -> 0 | D42: =+'QBR 2024'!C43 -> 3 | E42: =+C42-D42 -> -3 | G42: =+'QBR 2025'!D43 -> 3 | H42: =+'QBR 2024'!D43 -> 0 | I42: =+G42-H42 -> 3 | K42: =+'QBR 2025'!E43 -> 2 | L42: =+'QBR 2024'!E43 -> 0 | M42: =+K42-L42 -> 2 | O42: =+'QBR 2025'!F43 -> 0 | P42: =+'QBR 2024'!F43 -> 0 | Q42: =+O42-P42 -> 0
B43: New MRR | C43: =+'QBR 2025'!C44 -> 0 | D43: =+'QBR 2024'!C44 -> 9528 | E43: =+C43-D43 -> -9528 | G43: =+'QBR 2025'!D44 -> 2902 | H43: =+'QBR 2024'!D44 -> 0 | I43: =+G43-H43 -> 2902 | K43: =+'QBR 2025'!E44 -> 2471 | L43: =+'QBR 2024'!E44 -> 100 | M43: =+K43-L43 -> 2371 | O43: =+'QBR 2025'!F44 -> 0 | P43: =+'QBR 2024'!F44 -> 0 | Q43: =+O43-P43 -> 0
B44: Lost MRR | C44: =+'QBR 2025'!C45 -> 182.4 | D44: =+'QBR 2024'!C45 -> 0 | E44: =+C44-D44 -> 182.4 | G44: =+'QBR 2025'!D45 -> 2354 | H44: =+'QBR 2024'!D45 -> 779.68 | I44: =+G44-H44 -> 1574.32 | K44: =+'QBR 2025'!E45 -> 12458.08 | L44: =+'QBR 2024'!E45 -> 0 | M44: =+K44-L44 -> 12458.08 | O44: =+'QBR 2025'!F45 -> 0 | P44: =+'QBR 2024'!F45 -> 0 | Q44: =+O44-P44 -> 0

Sheet SmartNumbers2025
A2: Quarterly Business Review
A4: Smart Numbers
A6: Category | B6: Q1 2025 | C6: Q2 2025 | D6: Q3 2025 | E6: Q4 2025
A7: Operations
A8: Reactive Tickets / Tech / Month (closed) | B8: =IF(ISERROR('QBR 2025'!C10/'QBR 2025'!C35/3),"--",'QBR 2025'!C10/'QBR 2025'!C35/3) -> 65.454545 | C8: =IF(ISERROR('QBR 2025'!D10/'QBR 2025'!D35/3),"--",'QBR 2025'!D10/'QBR 2025'!D35/3) -> 74.606061 | D8: =IF(ISERROR('QBR 2025'!E10/'QBR 2025'!E35/3),"--",'QBR 2025'!E10/'QBR 2025'!E35/3) -> 70.064516 | E8: =IF(ISERROR('QBR 2025'!F10/'QBR 2025'!F35/3),"--",'QBR 2025'!F10/'QBR 2025'!F35/3) -> 64.363636
A9: Total Close % | B9: =IF(ISERROR('QBR 2025'!C10/'QBR 2025'!C9),"--",'QBR 2025'!C10/'QBR 2025'!C9) -> 0.99907493 | C9: =IF(ISERROR('QBR 2025'!D10/'QBR 2025'!D9),"--",'QBR 2025'!D10/'QBR 2025'!D9) -> 0.99194198 | D9: =IF(ISERROR('QBR 2025'!E10/'QBR 2025'!E9),"--",'QBR 2025'!E10/'QBR 2025'!E9) -> 1.0055556 | E9: =IF(ISERROR('QBR 2025'!F10/'QBR 2025'!F9),"--",'QBR 2025'!F10/'QBR 2025'!F9) -> 0.98060942
A10: Reactive Tickets / Endpoint / Month (new) | B10: =IF(ISERROR('QBR 2025'!C9/3/'QBR 2025'!C12),"--",'QBR 2025'!C9/3/'QBR 2025'!C12) -> 0.60662177 | C10: =IF(ISERROR('QBR 2025'!D9/3/'QBR 2025'!D12),"--",'QBR 2025'!D9/3/'QBR 2025'!D12) -> 0.66936354 | D10: =IF(ISERROR('QBR 2025'!E9/3/'QBR 2025'!E12),"--",'QBR 2025'!E9/3/'QBR 2025'!E12) -> 0.62973761 | E10: =IF(ISERROR('QBR 2025'!F9/3/'QBR 2025'!F12),"--",'QBR 2025'!F9/3/'QBR 2025'!F12) -> 0.31282496
A11: RHEM (Reactive Hours / Endpoint / Month) | B11: =IF(ISERROR('QBR 2025'!C11/'QBR 2025'!C12/3),"--",'QBR 2025'!C11/'QBR 2025'!C12/3) -> 0.25375982 | C11: =IF(ISERROR('QBR 2025'!D11/'QBR 2025'!D12/3),"--",'QBR 2025'!D11/'QBR 2025'!D12/3) -> 0.21586839 | D11: =IF(ISERROR('QBR 2025'!E11/'QBR 2025'!E12/3),"--",'QBR 2025'!E11/'QBR 2025'!E12/3) -> 0 | E11: =IF(ISERROR('QBR 2025'!F11/'QBR 2025'!F12/3),"--",'QBR 2025'!F11/'QBR 2025'!F12/3) -> 0
A12: Average Resolution Time | B12: =IF(ISERROR('QBR 2025'!C11/'QBR 2025'!C10),"--",'QBR 2025'!C11/'QBR 2025'!C10) -> 0.4187037 | C12: =IF(ISERROR('QBR 2025'!D11/'QBR 2025'!D10),"--",'QBR 2025'!D11/'QBR 2025'!D10) -> 0.32511779 | D12: =IF(ISERROR('QBR 2025'!E11/'QBR 2025'!E10),"--",'QBR 2025'!E11/'QBR 2025'!E10) -> 0 | E12: =IF(ISERROR('QBR 2025'!F11/'QBR 2025'!F10),"--",'QBR 2025'!F11/'QBR 2025'!F10) -> 0
A13: Reactive Service % | B13: =IF(ISERROR('QBR 2025'!C11/3/('QBR 2025'!C35*167)),"--",'QBR 2025'!C11/3/('QBR 2025'!C35*167)) -> 0.16410815 | C13: =IF(ISERROR('QBR 2025'!D11/3/('QBR 2025'!D35*167)),"--",'QBR 2025'!D11/3/('QBR 2025'!D35*167)) -> 0.14524406 | D13: =IF(ISERROR('QBR 2025'!E11/3/('QBR 2025'!E35*167)),"--",'QBR 2025'!E11/3/('QBR 2025'!E35*167)) -> 0 | E13: =IF(ISERROR('QBR 2025'!F11/3/('QBR 2025'!F35*167)),"--",'QBR 2025'!F11/3/('QBR 2025'!F35*167)) -> 0
A14: Profit
A15: Net Profit % | B15: =IF(ISERROR('QBR 2025'!C31/'QBR 2025'!C20),"--",'QBR 2025'!C31/'QBR 2025'!C20) -> 0.10475789 | C15: =IF(ISERROR('QBR 2025'!D31/'QBR 2025'!D20),"--",'QBR 2025'!D31/'QBR 2025'!D20) -> 0.10855307 | D15: =IF(ISERROR('QBR 2025'!E31/'QBR 2025'!E20),"--",'QBR 2025'!E31/'QBR 2025'!E20) -> 0.11865078 | E15: =IF(ISERROR('QBR 2025'!F31/'QBR 2025'!F20),"--",'QBR 2025'!F31/'QBR 2025'!F20) -> 0.17389481 | F15: =IF(ISERROR('QBR 2025'!G31/'QBR 2025'!G20),"--",'QBR 2025'!G31/'QBR 2025'!G20) -> 0.11752542
A17: Revenue
A18: % of Revenue from Services | B18: =IF(ISERROR(SUM('QBR 2025'!C15:C16)/'QBR 2025'!C20),"--",SUM('QBR 2025'!C15:C16)/'QBR 2025'!C20) -> 0.7027094 | C18: =IF(ISERROR(SUM('QBR 2025'!D15:D16)/'QBR 2025'!D20),"--",SUM('QBR 2025'!D15:D16)/'QBR 2025'!D20) -> 0.75389759 | D18: =IF(ISERROR(SUM('QBR 2025'!E15:E16)/'QBR 2025'!E20),"--",SUM('QBR 2025'!E15:E16)/'QBR 2025'!E20) -> 0.70153245 | E18: =IF(ISERROR(SUM('QBR 2025'!F15:F16)/'QBR 2025'!F20),"--",SUM('QBR 2025'!F15:F16)/'QBR 2025'!F20) -> 0.72100045
A19: % of Services from MRR | B19: =IF(ISERROR('QBR 2025'!C16/('QBR 2025'!C15+'QBR 2025'!C16)),"--",'QBR 2025'!C16/('QBR 2025'!C15+'QBR 2025'!C16)) -> 0.91089069 | C19: =IF(ISERROR('QBR 2025'!D16/('QBR 2025'!D15+'QBR 2025'!D16)),"--",'QBR 2025'!D16/('QBR 2025'!D15+'QBR 2025'!D16)) -> 0.97344501 | D19: =IF(ISERROR('QBR 2025'!E16/('QBR 2025'!E15+'QBR 2025'!E16)),"--",'QBR 2025'!E16/('QBR 2025'!E15+'QBR 2025'!E16)) -> 0.92108387 | E19: =IF(ISERROR('QBR 2025'!F16/('QBR 2025'!F15+'QBR 2025'!F16)),"--",'QBR 2025'!F16/('QBR 2025'!F15+'QBR 2025'!F16)) -> 0.8370466
A21: Leverage
A22: Annualized Service Revenue / Employee | B22: =IF(ISERROR(SUM('QBR 2025'!C$15:C$17)/'QBR 2025'!C$34*4),"--",SUM('QBR 2025'!C$15:C$17)/'QBR 2025'!C$34*4) -> 220817.96 | C22: =IF(ISERROR(SUM('QBR 2025'!D$15:D$17)/'QBR 2025'!D$34*4),"--",SUM('QBR 2025'!D$15:D$17)/'QBR 2025'!D$34*4) -> 204723.33 | D22: =IF(ISERROR(SUM('QBR 2025'!E$15:E$17)/'QBR 2025'!E$34*4),"--",SUM('QBR 2025'!E$15:E$17)/'QBR 2025'!E$34*4) -> 202289.38 | E22: =IF(ISERROR(SUM('QBR 2025'!F$15:F$17)/'QBR 2025'!F$34*4),"--",SUM('QBR 2025'!F$15:F$17)/'QBR 2025'!F$34*4) -> 201653.55
A23: Annualized Service Revenue / Technical Employee | B23: =IF(ISERROR(SUM('QBR 2025'!C$15:C$17)/'QBR 2025'!C$35*4),"--",SUM('QBR 2025'!C$15:C$17)/'QBR 2025'!C$35*4) -> 341264.12 | C23: =IF(ISERROR(SUM('QBR 2025'!D$15:D$16)/'QBR 2025'!D$35*4),"--",SUM('QBR 2025'!D$15:D$16)/'QBR 2025'!D$35*4) -> 256130.16 | D23: =IF(ISERROR(SUM('QBR 2025'!E$15:E$16)/'QBR 2025'!E$35*4),"--",SUM('QBR 2025'!E$15:E$16)/'QBR 2025'!E$35*4) -> 275476.61 | E23: =IF(ISERROR(SUM('QBR 2025'!F$15:F$16)/'QBR 2025'!F$35*4),"--",SUM('QBR 2025'!F$15:F$16)/'QBR 2025'!F$35*4) -> 284708.27
A24: Average AISP | B24: =IF(ISERROR('QBR 2025'!C16/'QBR 2025'!C36/3),"--",'QBR 2025'!C16/'QBR 2025'!C36/3) -> 202.30506 | C24: =IF(ISERROR('QBR 2025'!D16/'QBR 2025'!D36/3),"--",'QBR 2025'!D16/'QBR 2025'!D36/3) -> 201.66286 | D24: =IF(ISERROR('QBR 2025'!E16/'QBR 2025'!E36/3),"--",'QBR 2025'!E16/'QBR 2025'!E36/3) -> 209.02022 | E24: =IF(ISERROR('QBR 2025'!F16/'QBR 2025'!F36/3),"--",'QBR 2025'!F16/'QBR 2025'!F36/3) -> --
A25: Average MRR | B25: =IF(ISERROR('QBR 2025'!C16/'QBR 2025'!C37/3),"--",'QBR 2025'!C16/'QBR 2025'!C37/3) -> 3027.1519 | C25: =IF(ISERROR('QBR 2025'!D16/'QBR 2025'!D37/3),"--",'QBR 2025'!D16/'QBR 2025'!D37/3) -> 3033.866 | D25: =IF(ISERROR('QBR 2025'!E16/'QBR 2025'!E37/3),"--",'QBR 2025'!E16/'QBR 2025'!E37/3) -> 2900.3868 | E25: =IF(ISERROR('QBR 2025'!F16/'QBR 2025'!F37/3),"--",'QBR 2025'!F16/'QBR 2025'!F37/3) -> --
A27: Sales
A28: New MRR added | B28: =+'QBR 2025'!C44 -> 0 | C28: =+'QBR 2025'!D44 -> 2902 | D28: =+'QBR 2025'!E44 -> 2471 | E28: =+'QBR 2025'!F44 -> 0
A29: Lost MRR (churn) | B29: =+'QBR 2025'!C45 -> 182.4 | C29: =+'QBR 2025'!D45 -> 2354 | D29: =+'QBR 2025'!E45 -> 12458.08 | E29: =+'QBR 2025'!F45 -> 0
A30: Net MRR gain | B30: =B28-B29 -> -182.4 | C30: =C28-C29 -> 548 | D30: =D28-D29 -> -9987.08 | E30: =E28-E29 -> 0
A31: # of dials / appointment | B31: =IF(ISERROR('QBR 2025'!C40/'QBR 2025'!C41),"--",'QBR 2025'!C40/'QBR 2025'!C41) -> -- | C31: =IF(ISERROR('QBR 2025'!D40/'QBR 2025'!D41),"--",'QBR 2025'!D40/'QBR 2025'!D41) -> 0 | D31: =IF(ISERROR('QBR 2025'!E40/'QBR 2025'!E41),"--",'QBR 2025'!E40/'QBR 2025'!E41) -> 0 | E31: =IF(ISERROR('QBR 2025'!F40/'QBR 2025'!F41),"--",'QBR 2025'!F40/'QBR 2025'!F41) -> 0
A32: # of first appointments | B32: ='QBR 2025'!C41 -> 0 | C32: ='QBR 2025'!D41 -> 3 | D32: ='QBR 2025'!E41 -> 4 | E32: ='QBR 2025'!F41 -> 3
A33: Sales Call Close % | B33: =IF(ISERROR('QBR 2025'!C43/'QBR 2025'!C41),"--",'QBR 2025'!C43/'QBR 2025'!C41) -> -- | C33: =IF(ISERROR('QBR 2025'!D43/'QBR 2025'!D41),"--",'QBR 2025'!D43/'QBR 2025'!D41) -> 1 | D33: =IF(ISERROR('QBR 2025'!E43/'QBR 2025'!E41),"--",'QBR 2025'!E43/'QBR 2025'!E41) -> 0.5 | E33: =IF(ISERROR('QBR 2025'!F43/'QBR 2025'!F41),"--",'QBR 2025'!F43/'QBR 2025'!F41) -> 0

Sheet SmartNumbers2024-2025
A2: Quarterly Business Review
A4: Smart Numbers
A6: Category | B6: Q1 2024 | C6: Q2 2024 | D6: Q3 2024 | E6: Q4 2024 | F6: Q1 2025 | G6: Q2 2025 | H6: Q3 2025 | I6: Q4 2025
A7: Operations
A8: Reactive Tickets / Tech / Month (closed) | B8: =IF(ISERROR('QBR 2024'!C10/'QBR 2024'!C35/3),"--",'QBR 2024'!C10/'QBR 2024'!C35/3) -> 0 | C8: =IF(ISERROR('QBR 2024'!D10/'QBR 2024'!D35/3),"--",'QBR 2024'!D10/'QBR 2024'!D35/3) -> 0 | D8: =IF(ISERROR('QBR 2024'!E10/'QBR 2024'!E35/3),"--",'QBR 2024'!E10/'QBR 2024'!E35/3) -> 0 | E8: =IF(ISERROR('QBR 2024'!F10/'QBR 2024'!F35/3),"--",'QBR 2024'!F10/'QBR 2024'!F35/3) -> 0 | F8: =+SmartNumbers2025!B8 -> 65.454545 | G8: =+SmartNumbers2025!C8 -> 74.606061 | H8: =+SmartNumbers2025!D8 -> 70.064516 | I8: =+SmartNumbers2025!E8 -> 64.363636
A9: Total Close % | B9: =IF(ISERROR('QBR 2024'!C10/'QBR 2024'!C9),"--",'QBR 2024'!C10/'QBR 2024'!C9) -> -- | C9: =IF(ISERROR('QBR 2024'!D10/'QBR 2024'!D9),"--",'QBR 2024'!D10/'QBR 2024'!D9) -> -- | D9: =IF(ISERROR('QBR 2024'!E10/'QBR 2024'!E9),"--",'QBR 2024'!E10/'QBR 2024'!E9) -> -- | E9: =IF(ISERROR('QBR 2024'!F10/'QBR 2024'!F9),"--",'QBR 2024'!F10/'QBR 2024'!F9) -> -- | F9: =+SmartNumbers2025!B9 -> 0.99907493 | G9: =+SmartNumbers2025!C9 -> 0.99194198 | H9: =+SmartNumbers2025!D9 -> 1.0055556 | I9: =+SmartNumbers2025!E9 -> 0.98060942
A10: Reactive Tickets / Endpoint / Month (new) | B10: =IF(ISERROR('QBR 2024'!C9/3/'QBR 2024'!C12),"--",'QBR 2024'!C9/3/'QBR 2024'!C12) -> 0 | C10: =IF(ISERROR('QBR 2024'!D9/3/'QBR 2024'!D12),"--",'QBR 2024'!D9/3/'QBR 2024'!D12) -> 0 | D10: =IF(ISERROR('QBR 2024'!E9/3/'QBR 2024'!E12),"--",'QBR 2024'!E9/3/'QBR 2024'!E12) -> 0 | E10: =IF(ISERROR('QBR 2024'!F9/3/'QBR 2024'!F12),"--",'QBR 2024'!F9/3/'QBR 2024'!F12) -> 0 | F10: =+SmartNumbers2025!B10 -> 0.60662177 | G10: =+SmartNumbers2025!C10 -> 0.66936354 | H10: =+SmartNumbers2025!D10 -> 0.62973761 | I10: =+SmartNumbers2025!E10 -> 0.31282496
A11: RHEM (Reactive Hours / Endpoint / Month) | B11: =IF(ISERROR('QBR 2024'!C11/'QBR 2024'!C12/3),"--",'QBR 2024'!C11/'QBR 2024'!C12/3) -> 0 | C11: =IF(ISERROR('QBR 2024'!D11/'QBR 2024'!D12/3),"--",'QBR 2024'!D11/'QBR 2024'!D12/3) -> 0 | D11: =IF(ISERROR('QBR 2024'!E11/'QBR 2024'!E12/3),"--",'QBR 2024'!E11/'QBR 2024'!E12/3) -> 0 | E11: =IF(ISERROR('QBR 2024'!F11/'QBR 2024'!F12/3),"--",'QBR 2024'!F11/'QBR 2024'!F12/3) -> 0 | F11: =+SmartNumbers2025!B11 -> 0.25375982 | G11: =+SmartNumbers2025!C11 -> 0.21586839 | H11: =+SmartNumbers2025!D11 -> 0 | I11: =+SmartNumbers2025!E11 -> 0
A12: Average Resolution Time | B12: =IF(ISERROR('QBR 2024'!C11/'QBR 2024'!C10),"--",'QBR 2024'!C11/'QBR 2024'!C10) -> -- | C12: =IF(ISERROR('QBR 2024'!D11/'QBR 2024'!D10),"--",'QBR 2024'!D11/'QBR 2024'!D10) -> -- | D12: =IF(ISERROR('QBR 2024'!E11/'QBR 2024'!E10),"--",'QBR 2024'!E11/'QBR 2024'!E10) -> -- | E12: =IF(ISERROR('QBR 2024'!F11/'QBR 2024'!F10),"--",'QBR 2024'!F11/'QBR 2024'!F10) -> -- | F12: =+SmartNumbers2025!B12 -> 0.4187037 | G12: =+SmartNumbers2025!C12 -> 0.32511779 | H12: =+SmartNumbers2025!D12 -> 0 | I12: =+SmartNumbers2025!E12 -> 0
A13: Reactive Service % | B13: =IF(ISERROR('QBR 2024'!C11/3/('QBR 2024'!C35*167)),"--",'QBR 2024'!C11/3/('QBR 2024'!C35*167)) -> 0 | C13: =IF(ISERROR('QBR 2024'!D11/3/('QBR 2024'!D35*167)),"--",'QBR 2024'!D11/3/('QBR 2024'!D35*167)) -> 0 | D13: =IF(ISERROR('QBR 2024'!E11/3/('QBR 2024'!E35*167)),"--",'QBR 2024'!E11/3/('QBR 2024'!E35*167)) -> 0 | E13: =IF(ISERROR('QBR 2024'!F11/3/('QBR 2024'!F35*167)),"--",'QBR 2024'!F11/3/('QBR 2024'!F35*167)) -> 0 | F13: =+SmartNumbers2025!B13 -> 0.16410815 | G13: =+SmartNumbers2025!C13 -> 0.14524406 | H13: =+SmartNumbers2025!D13 -> 0 | I13: =+SmartNumbers2025!E13 -> 0
A14: Profit
A15: Net Profit % | B15: =IF(ISERROR('QBR 2024'!C31/'QBR 2024'!C20),"--",'QBR 2024'!C31/'QBR 2024'!C20) -> 0.067217362 | C15: =IF(ISERROR('QBR 2024'!D31/'QBR 2024'!D20),"--",'QBR 2024'!D31/'QBR 2024'!D20) -> 0.048777761 | D15: =IF(ISERROR('QBR 2024'!E31/'QBR 2024'!E20),"--",'QBR 2024'!E31/'QBR 2024'!E20) -> 0.065176028 | E15: =IF(ISERROR('QBR 2024'!F31/'QBR 2024'!F20),"--",'QBR 2024'!F31/'QBR 2024'!F20) -> 0.069243069 | F15: =+SmartNumbers2025!B15 -> 0.10475789 | G15: =+SmartNumbers2025!C15 -> 0.10855307 | H15: =+SmartNumbers2025!D15 -> 0.11865078 | I15: =+SmartNumbers2025!E15 -> 0.17389481 | J15: =SmartNumbers2025!F15 -> 0.11752542 | K15: 2025
J16: 0.0628 | K16: 2024
A17: Revenue | J17: -0.019 | K17: 2023
A18: % of Revenue from Services | B18: =IF(ISERROR(SUM('QBR 2024'!C15:C16)/'QBR 2024'!C20),"--",SUM('QBR 2024'!C15:C16)/'QBR 2024'!C20) -> 0.70584687 | C18: =IF(ISERROR(SUM('QBR 2024'!D15:D16)/'QBR 2024'!D20),"--",SUM('QBR 2024'!D15:D16)/'QBR 2024'!D20) -> 0.73561324 | D18: =IF(ISERROR(SUM('QBR 2024'!E15:E16)/'QBR 2024'!E20),"--",SUM('QBR 2024'!E15:E16)/'QBR 2024'!E20) -> 0.77889381 | E18: =IF(ISERROR(SUM('QBR 2024'!F15:F16)/'QBR 2024'!F20),"--",SUM('QBR 2024'!F15:F16)/'QBR 2024'!F20) -> 0.71216372 | F18: =+SmartNumbers2025!B18 -> 0.7027094 | G18: =+SmartNumbers2025!C18 -> 0.75389759 | H18: =+SmartNumbers2025!D18 -> 0.70153245 | I18: =+SmartNumbers2025!E18 -> 0.72100045 | J18: 0.073030939 | K18: 2022
A19: % of Services from MRR | B19: =IF(ISERROR('QBR 2024'!C16/('QBR 2024'!C15+'QBR 2024'!C16)),"--",'QBR 2024'!C16/('QBR 2024'!C15+'QBR 2024'!C16)) -> 0.91560607 | C19: =IF(ISERROR('QBR 2024'!D16/('QBR 2024'!D15+'QBR 2024'!D16)),"--",'QBR 2024'!D16/('QBR 2024'!D15+'QBR 2024'!D16)) -> 0.93989566 | D19: =IF(ISERROR('QBR 2024'!E16/('QBR 2024'!E15+'QBR 2024'!E16)),"--",'QBR 2024'!E16/('QBR 2024'!E15+'QBR 2024'!E16)) -> 0.95622694 | E19: =IF(ISERROR('QBR 2024'!F16/('QBR 2024'!F15+'QBR 2024'!F16)),"--",'QBR 2024'!F16/('QBR 2024'!F15+'QBR 2024'!F16)) -> 0.92346534 | F19: =+SmartNumbers2025!B19 -> 0.91089069 | G19: =+SmartNumbers2025!C19 -> 0.97344501 | H19: =+SmartNumbers2025!D19 -> 0.92108387 | I19: =+SmartNumbers2025!E19 -> 0.8370466 | J19: 0.1907 | K19: 2021
J20: 0.15748813 | K20: 2020
A21: Leverage | J21: 0.15860908 | K21: 2019
A22: Annualized Service Revenue / Employee | B22: =IF(ISERROR(SUM('QBR 2024'!C$15:C$17)/'QBR 2024'!C$34*4),"--",SUM('QBR 2024'!C$15:C$17)/'QBR 2024'!C$34*4) -> 192828.91 | C22: =IF(ISERROR(SUM('QBR 2024'!D$15:D$17)/'QBR 2024'!D$34*4),"--",SUM('QBR 2024'!D$15:D$17)/'QBR 2024'!D$34*4) -> 176301.31 | D22: =IF(ISERROR(SUM('QBR 2024'!E$15:E$17)/'QBR 2024'!E$34*4),"--",SUM('QBR 2024'!E$15:E$17)/'QBR 2024'!E$34*4) -> 180016.96 | E22: =IF(ISERROR(SUM('QBR 2024'!F$15:F$17)/'QBR 2024'!F$34*4),"--",SUM('QBR 2024'!F$15:F$17)/'QBR 2024'!F$34*4) -> 202058.33 | F22: =+SmartNumbers2025!B22 -> 220817.96 | G22: =+SmartNumbers2025!C22 -> 204723.33 | H22: =+SmartNumbers2025!D22 -> 202289.38 | I22: =+SmartNumbers2025!E22 -> 201653.55 | J22: 0.0777 | K22: 2018
A23: Annualized Service Revenue / Technical Employee | B23: =IF(ISERROR(SUM('QBR 2024'!C$15:C$17)/'QBR 2024'!C$35*4),"--",SUM('QBR 2024'!C$15:C$17)/'QBR 2024'!C$35*4) -> 298008.31 | C23: =IF(ISERROR(SUM('QBR 2024'!D$15:D$17)/'QBR 2024'!D$35*4),"--",SUM('QBR 2024'!D$15:D$17)/'QBR 2024'!D$35*4) -> 272465.66 | D23: =IF(ISERROR(SUM('QBR 2024'!E$15:E$17)/'QBR 2024'!E$35*4),"--",SUM('QBR 2024'!E$15:E$17)/'QBR 2024'!E$35*4) -> 278208.04 | E23: =IF(ISERROR(SUM('QBR 2024'!F$15:F$17)/'QBR 2024'!F$35*4),"--",SUM('QBR 2024'!F$15:F$17)/'QBR 2024'!F$35*4) -> 312271.96 | F23: =+SmartNumbers2025!B23 -> 341264.12 | G23: =+SmartNumbers2025!C23 -> 256130.16 | H23: =+SmartNumbers2025!D23 -> 275476.61 | I23: =+SmartNumbers2025!E23 -> 284708.27 | J23: 0.0472 | K23: 2017
A24: Average AISP | B24: =IF(ISERROR('QBR 2024'!C16/'QBR 2024'!C36/3),"--",'QBR 2024'!C16/'QBR 2024'!C36/3) -> 200.96955 | C24: =IF(ISERROR('QBR 2024'!D16/'QBR 2024'!D36/3),"--",'QBR 2024'!D16/'QBR 2024'!D36/3) -> 201.98652 | D24: =IF(ISERROR('QBR 2024'!E16/'QBR 2024'!E36/3),"--",'QBR 2024'!E16/'QBR 2024'!E36/3) -> 201.99607 | E24: =IF(ISERROR('QBR 2024'!F16/'QBR 2024'!F36/3),"--",'QBR 2024'!F16/'QBR 2024'!F36/3) -> 198.96119 | F24: =+SmartNumbers2025!B24 -> 202.30506 | G24: =+SmartNumbers2025!C24 -> 201.66286 | H24: =+SmartNumbers2025!D24 -> 209.02022 | I24: =+SmartNumbers2025!E24 -> --
A25: Average MRR | B25: =IF(ISERROR('QBR 2024'!C16/'QBR 2024'!C37/3),"--",'QBR 2024'!C16/'QBR 2024'!C37/3) -> 2794.0621 | C25: =IF(ISERROR('QBR 2024'!D16/'QBR 2024'!D37/3),"--",'QBR 2024'!D16/'QBR 2024'!D37/3) -> 2928.8045 | D25: =IF(ISERROR('QBR 2024'!E16/'QBR 2024'!E37/3),"--",'QBR 2024'!E16/'QBR 2024'!E37/3) -> 2954.9139 | E25: =IF(ISERROR('QBR 2024'!F16/'QBR 2024'!F37/3),"--",'QBR 2024'!F16/'QBR 2024'!F37/3) -> 3050.7383 | F25: =+SmartNumbers2025!B25 -> 3027.1519 | G25: =+SmartNumbers2025!C25 -> 3033.866 | H25: =+SmartNumbers2025!D25 -> 2900.3868 | I25: =+SmartNumbers2025!E25 -> --
A27: Sales
A28: New MRR added | B28: ='QBR 2024'!C44 -> 9528 | C28: ='QBR 2024'!D44 -> 0 | D28: ='QBR 2024'!E44 -> 100 | E28: ='QBR 2024'!F44 -> 0 | F28: =+SmartNumbers2025!B28 -> 0 | G28: =+SmartNumbers2025!C28 -> 2902 | H28: =+SmartNumbers2025!D28 -> 2471 | I28: =+SmartNumbers2025!E28 -> 0
A29: Lost MRR (churn) | B29: ='QBR 2024'!C45 -> 0 | C29: ='QBR 2024'!D45 -> 779.68 | D29: ='QBR 2024'!E45 -> 0 | E29: ='QBR 2024'!F45 -> 0 | F29: =+SmartNumbers2025!B29 -> 182.4 | G29: =+SmartNumbers2025!C29 -> 2354 | H29: =+SmartNumbers2025!D29 -> 12458.08 | I29: =+SmartNumbers2025!E29 -> 0
A30: Net MRR gain | B30: =B28-B29 -> 9528 | C30: =C28-C29 -> -779.68 | D30: =D28-D29 -> 100 | E30: =E28-E29 -> 0 | F30: =+SmartNumbers2025!B30 -> -182.4 | G30: =+SmartNumbers2025!C30 -> 548 | H30: =+SmartNumbers2025!D30 -> -9987.08 | I30: =+SmartNumbers2025!E30 -> 0
A31: # of dials / appointment | B31: =IF(ISERROR('QBR 2024'!C40/'QBR 2024'!C41),"--",'QBR 2024'!C40/'QBR 2024'!C41) -> 0 | C31: =IF(ISERROR('QBR 2024'!D40/'QBR 2024'!D41),"--",'QBR 2024'!D40/'QBR 2024'!D41) -> 0 | D31: =IF(ISERROR('QBR 2024'!E40/'QBR 2024'!E41),"--",'QBR 2024'!E40/'QBR 2024'!E41) -> -- | E31: =IF(ISERROR('QBR 2024'!F40/'QBR 2024'!F41),"--",'QBR 2024'!F40/'QBR 2024'!F41) -> 0 | F31: =+SmartNumbers2025!B31 -> -- | G31: =+SmartNumbers2025!C31 -> 0 | H31: =+SmartNumbers2025!D31 -> 0 | I31: =+SmartNumbers2025!E31 -> 0
A32: # of first appointments | B32: ='QBR 2024'!C41 -> 12 | C32: ='QBR 2024'!D41 -> 4 | D32: ='QBR 2024'!E41 -> 0 | E32: ='QBR 2024'!F41 -> 2 | F32: =+SmartNumbers2025!B32 -> 0 | G32: =+SmartNumbers2025!C32 -> 3 | H32: =+SmartNumbers2025!D32 -> 4 | I32: =+SmartNumbers2025!E32 -> 3
A33: Sales Call Close % | B33: =IF(ISERROR('QBR 2024'!C43/'QBR 2024'!C41),"--",'QBR 2024'!C43/'QBR 2024'!C41) -> 0.25 | C33: =IF(ISERROR('QBR 2024'!D43/'QBR 2024'!D41),"--",'QBR 2024'!D43/'QBR 2024'!D41) -> 0 | D33: =IF(ISERROR('QBR 2024'!E43/'QBR 2024'!E41),"--",'QBR 2024'!E43/'QBR 2024'!E41) -> -- | E33: =IF(ISERROR('QBR 2024'!F43/'QBR 2024'!F41),"--",'QBR 2024'!F43/'QBR 2024'!F41) -> 0 | F33: =+SmartNumbers2025!B33 -> -- | G33: =+SmartNumbers2025!C33 -> 1 | H33: =+SmartNumbers2025!D33 -> 0.5 | I33: =+SmartNumbers2025!E33 -> 0

Sheet SmartNumbers2025byMonth
A2: Monthly Business Review
A4: Smart Numbers for 2025 by Month
A6: Category | B6: Jan | C6: Feb | D6: Mar | E6: Apr | F6: May | G6: June | H6: July | I6: August | J6: Sept | K6: Oct | L6: Nov | M6: Dec
A7: Operations
A8: Reactive Tickets / Tech / Month (closed) | B8: =IF(ISERROR(MonthlyINPUT!C10/MonthlyINPUT!C35),"--",MonthlyINPUT!C10/MonthlyINPUT!C35) -> 64.545455 | C8: =IF(ISERROR(MonthlyINPUT!D10/MonthlyINPUT!D35),"--",MonthlyINPUT!D10/MonthlyINPUT!D35) -> 53.454545 | D8: =IF(ISERROR(MonthlyINPUT!E10/MonthlyINPUT!E35),"--",MonthlyINPUT!E10/MonthlyINPUT!E35) -> 78.363636 | E8: =IF(ISERROR(MonthlyINPUT!F10/MonthlyINPUT!F35),"--",MonthlyINPUT!F10/MonthlyINPUT!F35) -> 67.818182 | F8: =IF(ISERROR(MonthlyINPUT!G10/MonthlyINPUT!G35),"--",MonthlyINPUT!G10/MonthlyINPUT!G35) -> 70 | G8: =IF(ISERROR(MonthlyINPUT!H10/MonthlyINPUT!H35),"--",MonthlyINPUT!H10/MonthlyINPUT!H35) -> 86 | H8: =IF(ISERROR(MonthlyINPUT!I10/MonthlyINPUT!I35),"--",MonthlyINPUT!I10/MonthlyINPUT!I35) -> 99.818182 | I8: =IF(ISERROR(MonthlyINPUT!J10/MonthlyINPUT!J35),"--",MonthlyINPUT!J10/MonthlyINPUT!J35) -> 44.727273 | ... M8: =IF(ISERROR(MonthlyINPUT!N10/MonthlyINPUT!N35),"--",MonthlyINPUT!N10/MonthlyINPUT!N35) -> --
A9: Total Close % | B9: =IF(ISERROR(MonthlyINPUT!C10/MonthlyINPUT!C9),"--",MonthlyINPUT!C10/MonthlyINPUT!C9) -> 1.0028249 | C9: =IF(ISERROR(MonthlyINPUT!D10/MonthlyINPUT!D9),"--",MonthlyINPUT!D10/MonthlyINPUT!D9) -> 1 | D9: =IF(ISERROR(MonthlyINPUT!E10/MonthlyINPUT!E9),"--",MonthlyINPUT!E10/MonthlyINPUT!E9) -> 0.99538106 | E9: =IF(ISERROR(MonthlyINPUT!F10/MonthlyINPUT!F9),"--",MonthlyINPUT!F10/MonthlyINPUT!F9) -> 0.98938992 | F9: =IF(ISERROR(MonthlyINPUT!G10/MonthlyINPUT!G9),"--",MonthlyINPUT!G10/MonthlyINPUT!G9) -> 0.99740933 | G9: =IF(ISERROR(MonthlyINPUT!H10/MonthlyINPUT!H9),"--",MonthlyINPUT!H10/MonthlyINPUT!H9) -> 0.98953975 | H9: =IF(ISERROR(MonthlyINPUT!I10/MonthlyINPUT!I9),"--",MonthlyINPUT!I10/MonthlyINPUT!I9) -> 1.0129151 | I9: =IF(ISERROR(MonthlyINPUT!J10/MonthlyINPUT!J9),"--",MonthlyINPUT!J10/MonthlyINPUT!J9) -> 0.98795181 | ... M9: =IF(ISERROR(MonthlyINPUT!N10/MonthlyINPUT!N9),"--",MonthlyINPUT!N10/MonthlyINPUT!N9) -> --
A10: Reactive Tickets / Endpoint / Month (new) | B10: =IF(ISERROR(MonthlyINPUT!C9/MonthlyINPUT!C12),"--",MonthlyINPUT!C9/MonthlyINPUT!C12) -> 0.59296482 | C10: =IF(ISERROR(MonthlyINPUT!D9/MonthlyINPUT!D12),"--",MonthlyINPUT!D9/MonthlyINPUT!D12) -> 0.49494949 | D10: =IF(ISERROR(MonthlyINPUT!E9/MonthlyINPUT!E12),"--",MonthlyINPUT!E9/MonthlyINPUT!E12) -> 0.73265651 | E10: =IF(ISERROR(MonthlyINPUT!F9/MonthlyINPUT!F12),"--",MonthlyINPUT!F9/MonthlyINPUT!F12) -> 0.61500816 | F10: =IF(ISERROR(MonthlyINPUT!G9/MonthlyINPUT!G12),"--",MonthlyINPUT!G9/MonthlyINPUT!G12) -> 0.603125 | G10: =IF(ISERROR(MonthlyINPUT!H9/MonthlyINPUT!H12),"--",MonthlyINPUT!H9/MonthlyINPUT!H12) -> 0.7953411 | H10: =IF(ISERROR(MonthlyINPUT!I9/MonthlyINPUT!I12),"--",MonthlyINPUT!I9/MonthlyINPUT!I12) -> 0.9078727 | I10: =IF(ISERROR(MonthlyINPUT!J9/MonthlyINPUT!J12),"--",MonthlyINPUT!J9/MonthlyINPUT!J12) -> 0.44464286 | ... M10: =IF(ISERROR(MonthlyINPUT!N9/MonthlyINPUT!N12),"--",MonthlyINPUT!N9/MonthlyINPUT!N12) -> --
A11: RHEM (Reactive Hours / Endpoint / Month) | B11: =IF(ISERROR(MonthlyINPUT!C11/MonthlyINPUT!C12),"--",MonthlyINPUT!C11/MonthlyINPUT!C12) -> 0.24532663 | C11: =IF(ISERROR(MonthlyINPUT!D11/MonthlyINPUT!D12),"--",MonthlyINPUT!D11/MonthlyINPUT!D12) -> 0.23282828 | D11: =IF(ISERROR(MonthlyINPUT!E11/MonthlyINPUT!E12),"--",MonthlyINPUT!E11/MonthlyINPUT!E12) -> 0.28331641 | E11: =IF(ISERROR(MonthlyINPUT!F11/MonthlyINPUT!F12),"--",MonthlyINPUT!F11/MonthlyINPUT!F12) -> 0.33420881 | F11: =IF(ISERROR(MonthlyINPUT!G11/MonthlyINPUT!G12),"--",MonthlyINPUT!G11/MonthlyINPUT!G12) -> 0.23176563 | G11: =IF(ISERROR(MonthlyINPUT!H11/MonthlyINPUT!H12),"--",MonthlyINPUT!H11/MonthlyINPUT!H12) -> 0.078236273 | H11: =IF(ISERROR(MonthlyINPUT!I11/MonthlyINPUT!I12),"--",MonthlyINPUT!I11/MonthlyINPUT!I12) -> 0 | I11: =IF(ISERROR(MonthlyINPUT!J11/MonthlyINPUT!J12),"--",MonthlyINPUT!J11/MonthlyINPUT!J12) -> 0 | ... M11: =IF(ISERROR(MonthlyINPUT!N11/MonthlyINPUT!N12),"--",MonthlyINPUT!N11/MonthlyINPUT!N12) -> --
A12: Average Resolution Time | B12: =IF(ISERROR(MonthlyINPUT!C11/MonthlyINPUT!C10),"--",MonthlyINPUT!C11/MonthlyINPUT!C10) -> 0.41256338 | C12: =IF(ISERROR(MonthlyINPUT!D11/MonthlyINPUT!D10),"--",MonthlyINPUT!D11/MonthlyINPUT!D10) -> 0.47040816 | D12: =IF(ISERROR(MonthlyINPUT!E11/MonthlyINPUT!E10),"--",MonthlyINPUT!E11/MonthlyINPUT!E10) -> 0.38849188 | E12: =IF(ISERROR(MonthlyINPUT!F11/MonthlyINPUT!F10),"--",MonthlyINPUT!F11/MonthlyINPUT!F10) -> 0.54924933 | F12: =IF(ISERROR(MonthlyINPUT!G11/MonthlyINPUT!G10),"--",MonthlyINPUT!G11/MonthlyINPUT!G10) -> 0.38527273 | G12: =IF(ISERROR(MonthlyINPUT!H11/MonthlyINPUT!H10),"--",MonthlyINPUT!H11/MonthlyINPUT!H10) -> 0.099408034 | H12: =IF(ISERROR(MonthlyINPUT!I11/MonthlyINPUT!I10),"--",MonthlyINPUT!I11/MonthlyINPUT!I10) -> 0 | I12: =IF(ISERROR(MonthlyINPUT!J11/MonthlyINPUT!J10),"--",MonthlyINPUT!J11/MonthlyINPUT!J10) -> 0 | ... M12: =IF(ISERROR(MonthlyINPUT!N11/MonthlyINPUT!N10),"--",MonthlyINPUT!N11/MonthlyINPUT!N10) -> --
